Workbook

Sheet CONTROL DE VERSIONES
D8: Diseño de registro de la interfaz de datos fiscales y personales IRPF 2025 para empresas de desarrollo
D9: Ejercicio.: | F9: 2025
D10: Autor: | E10: SG Aplicaciones | F10: Fecha: | G10: 46083 | H10: versión | I10: 1.0
D13: Revisiones
D15: Edi. | E15: Rev. | F15: Fecha | G15: Descripción de los cambios | H15: A (*) | I15: Páginas
D21: (*) Acción: A= Añadir; R= Reemplazar;
D26: Estado de aceptación
F28: Fecha | G28: Nombre
D29: Preparado por:
D30: Autorizado por:
D31: Aceptado por:
E63: Interfaz V1.3
E66: IRPF | F66: =F9 -> 2025 | G66: =CONCATENATE(" ",E66," ",F66) -> IRPF 2025
E67: IRPF | F67: =F9 -> 2025 | G67: =CONCATENATE(" ",E67," ",F67) -> IRPF 2025
E68: IRPF | F68: =F9 -> 2025 | G68: =CONCATENATE(" ",E68," ",F68) -> IRPF 2025
E69: versión | F69: =I10 -> 1.0 | G69: =CONCATENATE(E69," ",F69) -> versión 1.0

Sheet Introduccion y datos tecnicos
C2: ='CONTROL DE VERSIONES'!G69 -> versión 1.0 | G2: Diseño de registro de datos fiscales y personales
G3: ='CONTROL DE VERSIONES'!G66 -> IRPF 2025
G4: Introducción y datos técnicos.
C9: Introducción al documento de interfaz de datos fiscales y personales Este documento describe los diferentes conceptos de la interfaz de datos fiscales y personales IRPF 2025 que se ofrece para programas de ayuda desarrollados por empresas externas a la AEAT. El documento no incluye descripción ni asistencia sobre los criterios de tratamiento fiscal de los datos. No hay indicación de las partidas del modelo 100 sobre las que dichos datos tengan que ser reflejados (no hay una relación directa, pues puede haber combinaciones de varios datos sobre una partida, condiciones, etc.). Los datos ofrecidos son los utilizados por RentaWeb, y no denotan correspondencia directa con declaraciones presentadas relacionadas con el contribuyente. El contribuyente (y sus representantes) debe revisar la información antes de presentar la declaración. Se proporcionará en un documento aparte los detalles técnicos de conexión y autenticación frente al servicio de entrega del fichero de datos fiscales y personales. Todos los importes se entregan en céntimos de euro salvo que se especifique lo contrario. Los importes negativos se representan con una N en la primera posición. Ejemplo, para un importe de longitud 13, y cuantía '-100,00' se representaría con el valor N000000010000
C11: =IF(P11=TRUE,#REF!+1,) -> 0 | N11: =ISTEXT(D11) -> FALSE | O11: =ISNUMBER(D11) -> FALSE | P11: =OR(N11=TRUE,O11=TRUE) -> FALSE
C12: =IF(P12=TRUE,C11+1,) -> 0 | N12: =ISTEXT(D12) -> FALSE | O12: =ISNUMBER(D12) -> FALSE | P12: =OR(N12=TRUE,O12=TRUE) -> FALSE
C13: =IF(P13=TRUE,C12+1,) -> 0 | N13: =ISTEXT(D13) -> FALSE | O13: =ISNUMBER(D13) -> FALSE | P13: =OR(N13=TRUE,O13=TRUE) -> FALSE
C14: =IF(P14=TRUE,C13+1,) -> 0 | N14: =ISTEXT(D14) -> FALSE | O14: =ISNUMBER(D14) -> FALSE | P14: =OR(N14=TRUE,O14=TRUE) -> FALSE
C15: =IF(P15=TRUE,C14+1,) -> 0 | N15: =ISTEXT(D15) -> FALSE | O15: =ISNUMBER(D15) -> FALSE | P15: =OR(N15=TRUE,O15=TRUE) -> FALSE
C16: =IF(P16=TRUE,C15+1,) -> 0 | N16: =ISTEXT(D16) -> FALSE | O16: =ISNUMBER(D16) -> FALSE | P16: =OR(N16=TRUE,O16=TRUE) -> FALSE
C17: =IF(P17=TRUE,C16+1,) -> 0 | N17: =ISTEXT(D17) -> FALSE | O17: =ISNUMBER(D17) -> FALSE | P17: =OR(N17=TRUE,O17=TRUE) -> FALSE
C18: =IF(P18=TRUE,C17+1,) -> 0 | N18: =ISTEXT(D18) -> FALSE | O18: =ISNUMBER(D18) -> FALSE | P18: =OR(N18=TRUE,O18=TRUE) -> FALSE
C19: =IF(P19=TRUE,C18+1,) -> 0 | N19: =ISTEXT(D19) -> FALSE | O19: =ISNUMBER(D19) -> FALSE | P19: =OR(N19=TRUE,O19=TRUE) -> FALSE
C20: =IF(P20=TRUE,C19+1,) -> 0 | N20: =ISTEXT(D20) -> FALSE | O20: =ISNUMBER(D20) -> FALSE | P20: =OR(N20=TRUE,O20=TRUE) -> FALSE
C21: =IF(P21=TRUE,C20+1,) -> 0 | N21: =ISTEXT(D21) -> FALSE | O21: =ISNUMBER(D21) -> FALSE | P21: =OR(N21=TRUE,O21=TRUE) -> FALSE
C22: =IF(P22=TRUE,C21+1,) -> 0 | N22: =ISTEXT(D22) -> FALSE | O22: =ISNUMBER(D22) -> FALSE | P22: =OR(N22=TRUE,O22=TRUE) -> FALSE
C23: =IF(P23=TRUE,C22+1,) -> 0 | N23: =ISTEXT(D23) -> FALSE | O23: =ISNUMBER(D23) -> FALSE | P23: =OR(N23=TRUE,O23=TRUE) -> FALSE
... C93: =IF(P93=TRUE,C92+1,) -> 0 | N93: =ISTEXT(D93) -> FALSE | O93: =ISNUMBER(D93) -> FALSE | P93: =OR(N93=TRUE,O93=TRUE) -> FALSE

Sheet INDICE
C2: ='CONTROL DE VERSIONES'!G69 -> versión 1.0 | G2: Diseño de registro de datos fiscales y personales para Empresas Externas
G3: ='CONTROL DE VERSIONES'!G67 -> IRPF 2025
E8: Registro tipo 0
E11: Registro de tipo 0
E14: Registro de tipo 1
D16: Código
E17: Registros de tipo 2
E106: Registros de tipo 3
E112: Registros de tipo 9
G116: Observaciones:
G117: Se señalan en color azul los conceptos de datos fiscales NUEVOS para IRPF 2025
G118: Se señalan en color verde los conceptos de datos fiscales que hayan sufrido algún cambio en el número de campos o en el listado de claves de sus campos para IRPF 2025 (dentro del concepto se señalan en color verde los campos que hayan sufrido algún cambio)

Sheet Registro de Cabecera
D2: Diseño de registro de datos fiscales y personales
D3: ='CONTROL DE VERSIONES'!G68 -> IRPF 2025
D4: Registro de cabecera
C5: =IF(P5=TRUE,C4+1,) -> 0
C6: =IF(P6=TRUE,C5+1,) -> 0
C7: Este concepto contiene el código del registro de cabecera.
C9: Nº | D9: Nombre | E9: Posición | F9: Longitud | G9: Descripción
C10: =IF(P10=TRUE,1,) -> 1 | D10: Tipo | E10: =IF(P10=TRUE,1,) -> 1 | F10: 1 | G10: Tipo de registro = '0' | N10: =ISTEXT(D10) -> TRUE | O10: =ISNUMBER(D10) -> FALSE | P10: =OR(N10=TRUE,O10=TRUE) -> TRUE
C11: =IF(P11=TRUE,C10+1,) -> 2 | D11: Código | E11: =IF(P11=TRUE,E10+F10,) -> 2 | F11: 8 | G11: Contenido: 'DDFF2025' | N11: =ISTEXT(D11) -> TRUE | O11: =ISNUMBER(D11) -> FALSE | P11: =OR(N11=TRUE,O11=TRUE) -> TRUE
C12: =IF(P12=TRUE,C11+1,) -> 0 | N12: =ISTEXT(D12) -> FALSE | O12: =ISNUMBER(D12) -> FALSE | P12: =OR(N12=TRUE,O12=TRUE) -> FALSE
C13: =IF(P13=TRUE,C12+1,) -> 0 | N13: =ISTEXT(D13) -> FALSE | O13: =ISNUMBER(D13) -> FALSE | P13: =OR(N13=TRUE,O13=TRUE) -> FALSE
C14: =IF(P14=TRUE,C13+1,) -> 0 | N14: =ISTEXT(D14) -> FALSE | O14: =ISNUMBER(D14) -> FALSE | P14: =OR(N14=TRUE,O14=TRUE) -> FALSE
C15: =IF(P15=TRUE,C14+1,) -> 0 | N15: =ISTEXT(D15) -> FALSE | O15: =ISNUMBER(D15) -> FALSE | P15: =OR(N15=TRUE,O15=TRUE) -> FALSE
C16: =IF(P16=TRUE,C15+1,) -> 0 | N16: =ISTEXT(D16) -> FALSE | O16: =ISNUMBER(D16) -> FALSE | P16: =OR(N16=TRUE,O16=TRUE) -> FALSE
C17: =IF(P17=TRUE,C16+1,) -> 0 | N17: =ISTEXT(D17) -> FALSE | O17: =ISNUMBER(D17) -> FALSE | P17: =OR(N17=TRUE,O17=TRUE) -> FALSE
C18: =IF(P18=TRUE,C17+1,) -> 0 | N18: =ISTEXT(D18) -> FALSE | O18: =ISNUMBER(D18) -> FALSE | P18: =OR(N18=TRUE,O18=TRUE) -> FALSE
C19: =IF(P19=TRUE,C18+1,) -> 0 | N19: =ISTEXT(D19) -> FALSE | O19: =ISNUMBER(D19) -> FALSE | P19: =OR(N19=TRUE,O19=TRUE) -> FALSE
C20: =IF(P20=TRUE,C19+1,) -> 0 | N20: =ISTEXT(D20) -> FALSE | O20: =ISNUMBER(D20) -> FALSE | P20: =OR(N20=TRUE,O20=TRUE) -> FALSE
C21: =IF(P21=TRUE,C20+1,) -> 0 | N21: =ISTEXT(D21) -> FALSE | O21: =ISNUMBER(D21) -> FALSE | P21: =OR(N21=TRUE,O21=TRUE) -> FALSE
C22: =IF(P22=TRUE,C21+1,) -> 0 | N22: =ISTEXT(D22) -> FALSE | O22: =ISNUMBER(D22) -> FALSE | P22: =OR(N22=TRUE,O22=TRUE) -> FALSE
C23: =IF(P23=TRUE,C22+1,) -> 0 | N23: =ISTEXT(D23) -> FALSE | O23: =ISNUMBER(D23) -> FALSE | P23: =OR(N23=TRUE,O23=TRUE) -> FALSE
... C97: =IF(P97=TRUE,C96+1,) -> 0 | N97: =ISTEXT(D97) -> FALSE | O97: =ISNUMBER(D97) -> FALSE | P97: =OR(N97=TRUE,O97=TRUE) -> FALSE

Sheet Fecha de proceso
D2: Diseño de registro de datos fiscales y personales
D3: ='CONTROL DE VERSIONES'!G68 -> IRPF 2025
D4: Fecha de proceso
C5: =IF(P5=TRUE,C4+1,) -> 0
C6: =IF(P6=TRUE,C5+1,) -> 0
C7: Este concepto de datos fiscales incluye la fecha de proceso donde se han generado los datos fiscales.
C9: Nº | D9: Nombre | E9: Posición | F9: Longitud | G9: Descripción
C10: =IF(P10=TRUE,1,) -> 1 | D10: Tipo | E10: =IF(P10=TRUE,1,) -> 1 | F10: 1 | G10: Tipo de registro = '1' | N10: =ISTEXT(D10) -> TRUE | O10: =ISNUMBER(D10) -> FALSE | P10: =OR(N10=TRUE,O10=TRUE) -> TRUE
C11: =IF(P11=TRUE,C10+1,) -> 2 | D11: Posiciones reservadas para la AEAT | E11: =IF(P11=TRUE,E10+F10,) -> 2 | F11: 50 | N11: =ISTEXT(D11) -> TRUE | O11: =ISNUMBER(D11) -> FALSE | P11: =OR(N11=TRUE,O11=TRUE) -> TRUE
C12: =IF(P12=TRUE,C11+1,) -> 3 | D12: Fecha de proceso | E12: =IF(P12=TRUE,E11+F11,) -> 52 | F12: 8 | G12: Fecha del proceso con formato AAAAMMDD | N12: =ISTEXT(D12) -> TRUE | O12: =ISNUMBER(D12) -> FALSE | P12: =OR(N12=TRUE,O12=TRUE) -> TRUE
C13: =IF(P13=TRUE,C12+1,) -> 0 | N13: =ISTEXT(D13) -> FALSE | O13: =ISNUMBER(D13) -> FALSE | P13: =OR(N13=TRUE,O13=TRUE) -> FALSE
C14: =IF(P14=TRUE,C13+1,) -> 0 | N14: =ISTEXT(D14) -> FALSE | O14: =ISNUMBER(D14) -> FALSE | P14: =OR(N14=TRUE,O14=TRUE) -> FALSE
C15: =IF(P15=TRUE,C14+1,) -> 0 | N15: =ISTEXT(D15) -> FALSE | O15: =ISNUMBER(D15) -> FALSE | P15: =OR(N15=TRUE,O15=TRUE) -> FALSE
C16: =IF(P16=TRUE,C15+1,) -> 0 | N16: =ISTEXT(D16) -> FALSE | O16: =ISNUMBER(D16) -> FALSE | P16: =OR(N16=TRUE,O16=TRUE) -> FALSE
C17: =IF(P17=TRUE,C16+1,) -> 0 | N17: =ISTEXT(D17) -> FALSE | O17: =ISNUMBER(D17) -> FALSE | P17: =OR(N17=TRUE,O17=TRUE) -> FALSE
C18: =IF(P18=TRUE,C17+1,) -> 0 | N18: =ISTEXT(D18) -> FALSE | O18: =ISNUMBER(D18) -> FALSE | P18: =OR(N18=TRUE,O18=TRUE) -> FALSE
C19: =IF(P19=TRUE,C18+1,) -> 0 | N19: =ISTEXT(D19) -> FALSE | O19: =ISNUMBER(D19) -> FALSE | P19: =OR(N19=TRUE,O19=TRUE) -> FALSE
C20: =IF(P20=TRUE,C19+1,) -> 0 | N20: =ISTEXT(D20) -> FALSE | O20: =ISNUMBER(D20) -> FALSE | P20: =OR(N20=TRUE,O20=TRUE) -> FALSE
C21: =IF(P21=TRUE,C20+1,) -> 0 | N21: =ISTEXT(D21) -> FALSE | O21: =ISNUMBER(D21) -> FALSE | P21: =OR(N21=TRUE,O21=TRUE) -> FALSE
C22: =IF(P22=TRUE,C21+1,) -> 0 | N22: =ISTEXT(D22) -> FALSE | O22: =ISNUMBER(D22) -> FALSE | P22: =OR(N22=TRUE,O22=TRUE) -> FALSE
C23: =IF(P23=TRUE,C22+1,) -> 0 | N23: =ISTEXT(D23) -> FALSE | O23: =ISNUMBER(D23) -> FALSE | P23: =OR(N23=TRUE,O23=TRUE) -> FALSE
C24: =IF(P24=TRUE,C23+1,) -> 0 | N24: =ISTEXT(D24) -> FALSE | O24: =ISNUMBER(D24) -> FALSE | P24: =OR(N24=TRUE,O24=TRUE) -> FALSE
... C97: =IF(P97=TRUE,C96+1,) -> 0 | N97: =ISTEXT(D97) -> FALSE | O97: =ISNUMBER(D97) -> FALSE | P97: =OR(N97=TRUE,O97=TRUE) -> FALSE

Sheet DOM - Datos del domicilio
D2: Diseño de registro de datos fiscales y personales
D3: ='CONTROL DE VERSIONES'!G68 -> IRPF 2025
D4: Datos del domicilio
C5: =IF(P5=TRUE,C4+1,) -> 0
C6: =IF(P6=TRUE,C5+1,) -> 0
C7: Este concepto de datos fiscales incluye los datos del domicilio
C9: Nº | D9: Nombre | E9: Posición | F9: Longitud | G9: Descripción
C10: =IF(P10=TRUE,1,) -> 1 | D10: Tipo | E10: =IF(P10=TRUE,1,) -> 1 | F10: 1 | G10: Tipo de registro = '2' | N10: =ISTEXT(D10) -> TRUE | O10: =ISNUMBER(D10) -> FALSE | P10: =OR(N10=TRUE,O10=TRUE) -> TRUE
C11: =IF(P11=TRUE,C10+1,) -> 2 | D11: Código | E11: =IF(P11=TRUE,E10+F10,) -> 2 | F11: 7 | G11: 'DOMnnnn' | N11: =ISTEXT(D11) -> TRUE | O11: =ISNUMBER(D11) -> FALSE | P11: =OR(N11=TRUE,O11=TRUE) -> TRUE
C12: =IF(P12=TRUE,C11+1,) -> 3 | D12: Posiciones reservadas para la AEAT | E12: =IF(P12=TRUE,E11+F11,) -> 9 | F12: 1 | N12: =ISTEXT(D12) -> TRUE | O12: =ISNUMBER(D12) -> FALSE | P12: =OR(N12=TRUE,O12=TRUE) -> TRUE
C13: =IF(P13=TRUE,C12+1,) -> 4 | D13: Tipo domicilio | E13: =IF(P13=TRUE,E12+F12,) -> 10 | F13: 2 | G13: Valores: '20' - Domicilio fiscal en territorio español '21' - Domicilio fiscal en el extranjero | N13: =ISTEXT(D13) -> TRUE | O13: =ISNUMBER(D13) -> FALSE | P13: =OR(N13=TRUE,O13=TRUE) -> TRUE
C14: =IF(P14=TRUE,C13+1,) -> 5 | D14: Datos domicilio | E14: =IF(P14=TRUE,E13+F13,) -> 12 | F14: XXX | G14: Longitud dependiente del tipo de domicilio "20" o "21" | N14: =ISTEXT(D14) -> TRUE | O14: =ISNUMBER(D14) -> FALSE | P14: =OR(N14=TRUE,O14=TRUE) -> TRUE
C15: =IF(P15=TRUE,C14+1,) -> 0 | N15: =ISTEXT(D15) -> FALSE | O15: =ISNUMBER(D15) -> FALSE | P15: =OR(N15=TRUE,O15=TRUE) -> FALSE
C16: =IF(P16=TRUE,C15+1,) -> 0 | N16: =ISTEXT(D16) -> FALSE | O16: =ISNUMBER(D16) -> FALSE | P16: =OR(N16=TRUE,O16=TRUE) -> FALSE
C17: REDEFINICION DEL CAMPO 'DATOS DOMICILIO' PARA REGISTRO TIPO DE DOMICILIO '20' (en territorio español) | N17: =ISTEXT(D17) -> FALSE | O17: =ISNUMBER(D17) -> FALSE | P17: =OR(N17=TRUE,O17=TRUE) -> FALSE
N18: =ISTEXT(D18) -> FALSE | O18: =ISNUMBER(D18) -> FALSE | P18: =OR(N18=TRUE,O18=TRUE) -> FALSE
C19: =IF(P19=TRUE,1,) -> 1 | D19: Tipo de via | E19: =IF(P19=TRUE,12,) -> 12 | F19: 5 | G19: Tipo de vía según las tablas INE "Tipos de vías" | N19: =ISTEXT(D19) -> TRUE | O19: =ISNUMBER(D19) -> FALSE | P19: =OR(N19=TRUE,O19=TRUE) -> TRUE
C20: =IF(P20=TRUE,C19+1,) -> 2 | D20: Codigo de via | E20: =IF(P20=TRUE,E19+F19,) -> 17 | F20: 5 | G20: Código de vía según las tablas INE | N20: =ISTEXT(D20) -> TRUE | O20: =ISNUMBER(D20) -> FALSE | P20: =OR(N20=TRUE,O20=TRUE) -> TRUE
C21: =IF(P21=TRUE,C20+1,) -> 3 | D21: Nombre largo de la via | E21: =IF(P21=TRUE,E20+F20,) -> 22 | F21: 50 | N21: =ISTEXT(D21) -> TRUE | O21: =ISNUMBER(D21) -> FALSE | P21: =OR(N21=TRUE,O21=TRUE) -> TRUE
C22: =IF(P22=TRUE,C21+1,) -> 4 | D22: Nombre corto de la via | E22: =IF(P22=TRUE,E21+F21,) -> 72 | F22: 25 | N22: =ISTEXT(D22) -> TRUE | O22: =ISNUMBER(D22) -> FALSE | P22: =OR(N22=TRUE,O22=TRUE) -> TRUE
C23: =IF(P23=TRUE,C22+1,) -> 5 | D23: Tipo de numeracion | E23: =IF(P23=TRUE,E22+F22,) -> 97 | F23: 3 | G23: Valores: NUM; KM; S/N; APC; etc | N23: =ISTEXT(D23) -> TRUE | O23: =ISNUMBER(D23) -> FALSE | P23: =OR(N23=TRUE,O23=TRUE) -> TRUE
C24: =IF(P24=TRUE,C23+1,) -> 6 | D24: Numero | E24: =IF(P24=TRUE,E23+F23,) -> 100 | F24: 5 | N24: =ISTEXT(D24) -> TRUE | O24: =ISNUMBER(D24) -> FALSE | P24: =OR(N24=TRUE,O24=TRUE) -> TRUE
C25: =IF(P25=TRUE,C24+1,) -> 7 | D25: Calificador numero | E25: =IF(P25=TRUE,E24+F24,) -> 105 | F25: 3 | G25: Valores: BIS; DUP; MOD; ANT; etc | N25: =ISTEXT(D25) -> TRUE | O25: =ISNUMBER(D25) -> FALSE | P25: =OR(N25=TRUE,O25=TRUE) -> TRUE
C26: =IF(P26=TRUE,C25+1,) -> 8 | D26: Bloque | E26: =IF(P26=TRUE,E25+F25,) -> 108 | F26: 3 | N26: =ISTEXT(D26) -> TRUE | O26: =ISNUMBER(D26) -> FALSE | P26: =OR(N26=TRUE,O26=TRUE) -> TRUE
C27: =IF(P27=TRUE,C26+1,) -> 9 | D27: Portal | E27: =IF(P27=TRUE,E26+F26,) -> 111 | F27: 3 | N27: =ISTEXT(D27) -> TRUE | O27: =ISNUMBER(D27) -> FALSE | P27: =OR(N27=TRUE,O27=TRUE) -> TRUE
C28: =IF(P28=TRUE,C27+1,) -> 10 | D28: Escalera | E28: =IF(P28=TRUE,E27+F27,) -> 114 | F28: 3 | N28: =ISTEXT(D28) -> TRUE | O28: =ISNUMBER(D28) -> FALSE | P28: =OR(N28=TRUE,O28=TRUE) -> TRUE
C29: =IF(P29=TRUE,C28+1,) -> 11 | D29: Planta-piso | E29: =IF(P29=TRUE,E28+F28,) -> 117 | F29: 3 | N29: =ISTEXT(D29) -> TRUE | O29: =ISNUMBER(D29) -> FALSE | P29: =OR(N29=TRUE,O29=TRUE) -> TRUE
C30: =IF(P30=TRUE,C29+1,) -> 12 | D30: Puerta | E30: =IF(P30=TRUE,E29+F29,) -> 120 | F30: 3 | N30: =ISTEXT(D30) -> TRUE | O30: =ISNUMBER(D30) -> FALSE | P30: =OR(N30=TRUE,O30=TRUE) -> TRUE
C31: =IF(P31=TRUE,C30+1,) -> 13 | D31: Datos complementarios | E31: =IF(P31=TRUE,E30+F30,) -> 123 | F31: 40 | N31: =ISTEXT(D31) -> TRUE | O31: =ISNUMBER(D31) -> FALSE | P31: =OR(N31=TRUE,O31=TRUE) -> TRUE
C32: =IF(P32=TRUE,C31+1,) -> 14 | D32: Poblacion | E32: =IF(P32=TRUE,E31+F31,) -> 163 | F32: 30 | G32: Nombre Localidad, Población, etc. Si es distinta al municipio | N32: =ISTEXT(D32) -> TRUE | O32: =ISNUMBER(D32) -> FALSE | P32: =OR(N32=TRUE,O32=TRUE) -> TRUE
C33: =IF(P33=TRUE,C32+1,) -> 15 | D33: Codigo postal | E33: =IF(P33=TRUE,E32+F32,) -> 193 | F33: 5 | N33: =ISTEXT(D33) -> TRUE | O33: =ISNUMBER(D33) -> FALSE | P33: =OR(N33=TRUE,O33=TRUE) -> TRUE
C34: =IF(P34=TRUE,C33+1,) -> 16 | D34: Codigo de municipio INE | E34: =IF(P34=TRUE,E33+F33,) -> 198 | F34: 5 | G34: Código Municipio INE | N34: =ISTEXT(D34) -> TRUE | O34: =ISNUMBER(D34) -> FALSE | P34: =OR(N34=TRUE,O34=TRUE) -> TRUE
C35: =IF(P35=TRUE,C34+1,) -> 17 | D35: Municipio | E35: =IF(P35=TRUE,E34+F34,) -> 203 | F35: 30 | G35: Nombre del municipio | N35: =ISTEXT(D35) -> TRUE | O35: =ISNUMBER(D35) -> FALSE | P35: =OR(N35=TRUE,O35=TRUE) -> TRUE
C36: =IF(P36=TRUE,C35+1,) -> 18 | D36: Codigo de provincia | E36: =IF(P36=TRUE,E35+F35,) -> 233 | F36: 2 | G36: Posibles valores: de 01 a 52 | N36: =ISTEXT(D36) -> TRUE | O36: =ISNUMBER(D36) -> FALSE | P36: =OR(N36=TRUE,O36=TRUE) -> TRUE
C37: =IF(P37=TRUE,C36+1,) -> 19 | D37: Provincia | E37: =IF(P37=TRUE,E36+F36,) -> 235 | F37: 20 | G37: Nombre de la provincia | N37: =ISTEXT(D37) -> TRUE | O37: =ISNUMBER(D37) -> FALSE | P37: =OR(N37=TRUE,O37=TRUE) -> TRUE
C38: =IF(P38=TRUE,C37+1,) -> 20 | D38: Referencia catastral | E38: =IF(P38=TRUE,E37+F37,) -> 255 | F38: 20 | G38: Referencia catastral del domicilio fiscal | N38: =ISTEXT(D38) -> TRUE | O38: =ISNUMBER(D38) -> FALSE | P38: =OR(N38=TRUE,O38=TRUE) -> TRUE
C39: =IF(P39=TRUE,C38+1,) -> 21 | D39: Fecha de modificación | E39: =IF(P39=TRUE,E38+F38,) -> 275 | F39: 8 | N39: =ISTEXT(D39) -> TRUE | O39: =ISNUMBER(D39) -> FALSE | P39: =OR(N39=TRUE,O39=TRUE) -> TRUE
N40: =ISTEXT(D40) -> FALSE | O40: =ISNUMBER(D40) -> FALSE | P40: =OR(N40=TRUE,O40=TRUE) -> FALSE
C41: =IF(P41=TRUE,C40+1,) -> 0 | N41: =ISTEXT(D41) -> FALSE | O41: =ISNUMBER(D41) -> FALSE | P41: =OR(N41=TRUE,O41=TRUE) -> FALSE
C42: REDEFINICION DEL CAMPO 'DATOS DOMICILIO' PARA REGISTRO TIPO DE DOMICILIO '21' (en el extranjero) | N42: =ISTEXT(D42) -> FALSE | O42: =ISNUMBER(D42) -> FALSE | P42: =OR(N42=TRUE,O42=TRUE) -> FALSE
...

Sheet FA - Familia numerosa
D2: Diseño de registro de datos fiscales y personales
D3: ='CONTROL DE VERSIONES'!G68 -> IRPF 2025
D4: Familia numerosa
C5: =IF(P5=TRUE,C4+1,) -> 0
C6: =IF(P6=TRUE,C5+1,) -> 0
C7: Este concepto de datos fiscales incluye los datos de familia numerosa con origen en el modelo 990
C9: Nº | D9: Nombre | E9: Posición | F9: Longitud | G9: Descripción
C10: =IF(P10=TRUE,1,) -> 1 | D10: Tipo | E10: =IF(P10=TRUE,1,) -> 1 | F10: 1 | G10: Tipo de registro = '2' | N10: =ISTEXT(D10) -> TRUE | O10: =ISNUMBER(D10) -> FALSE | P10: =OR(N10=TRUE,O10=TRUE) -> TRUE
C11: =IF(P11=TRUE,C10+1,) -> 2 | D11: Código | E11: =IF(P11=TRUE,E10+F10,) -> 2 | F11: 7 | G11: 'FAnnnnn' Donde 'Fannnnn' será siempre igual a 'FA00001' | N11: =ISTEXT(D11) -> TRUE | O11: =ISNUMBER(D11) -> FALSE | P11: =OR(N11=TRUE,O11=TRUE) -> TRUE
C12: =IF(P12=TRUE,C11+1,) -> 3 | D12: NIF del declarante | E12: =IF(P12=TRUE,E11+F11,) -> 9 | F12: 9 | N12: =ISTEXT(D12) -> TRUE | O12: =ISNUMBER(D12) -> FALSE | P12: =OR(N12=TRUE,O12=TRUE) -> TRUE
C13: =IF(P13=TRUE,C12+1,) -> 4 | D13: Nombre del declarante | E13: =IF(P13=TRUE,E12+F12,) -> 18 | F13: 40 | N13: =ISTEXT(D13) -> TRUE | O13: =ISNUMBER(D13) -> FALSE | P13: =OR(N13=TRUE,O13=TRUE) -> TRUE
C14: =IF(P14=TRUE,C13+1,) -> 5 | D14: Tipo de familia numerosa | E14: =IF(P14=TRUE,E13+F13,) -> 58 | F14: 1 | G14: Valores: 'G' - General 'E' - Especial | N14: =ISTEXT(D14) -> TRUE | O14: =ISNUMBER(D14) -> FALSE | P14: =OR(N14=TRUE,O14=TRUE) -> TRUE
C15: =IF(P15=TRUE,C14+1,) -> 6 | D15: Número de identificación familia numerosa | E15: =IF(P15=TRUE,E14+F14,) -> 59 | F15: 30 | N15: =ISTEXT(D15) -> TRUE | O15: =ISNUMBER(D15) -> FALSE | P15: =OR(N15=TRUE,O15=TRUE) -> TRUE
C16: =IF(P16=TRUE,C15+1,) -> 7 | D16: Posiciones reservadas para la AEAT | E16: =IF(P16=TRUE,E15+F15,) -> 89 | F16: 2 | N16: =ISTEXT(D16) -> TRUE | O16: =ISNUMBER(D16) -> FALSE | P16: =OR(N16=TRUE,O16=TRUE) -> TRUE
C17: =IF(P17=TRUE,C16+1,) -> 0 | E17: =IF(P17=TRUE,E16+F16,) -> 0 | N17: =ISTEXT(D17) -> FALSE | O17: =ISNUMBER(D17) -> FALSE | P17: =OR(N17=TRUE,O17=TRUE) -> FALSE
C18: =IF(P18=TRUE,C17+1,) -> 0 | E18: =IF(P18=TRUE,E17+F17,) -> 0 | N18: =ISTEXT(D18) -> FALSE | O18: =ISNUMBER(D18) -> FALSE | P18: =OR(N18=TRUE,O18=TRUE) -> FALSE
C19: =IF(P19=TRUE,C18+1,) -> 0 | E19: =IF(P19=TRUE,E18+F18,) -> 0 | N19: =ISTEXT(D19) -> FALSE | O19: =ISNUMBER(D19) -> FALSE | P19: =OR(N19=TRUE,O19=TRUE) -> FALSE
C20: =IF(P20=TRUE,C19+1,) -> 0 | E20: =IF(P20=TRUE,E19+F19,) -> 0 | N20: =ISTEXT(D20) -> FALSE | O20: =ISNUMBER(D20) -> FALSE | P20: =OR(N20=TRUE,O20=TRUE) -> FALSE
C21: =IF(P21=TRUE,C20+1,) -> 0 | E21: =IF(P21=TRUE,E20+F20,) -> 0 | N21: =ISTEXT(D21) -> FALSE | O21: =ISNUMBER(D21) -> FALSE | P21: =OR(N21=TRUE,O21=TRUE) -> FALSE
C22: =IF(P22=TRUE,C21+1,) -> 0 | E22: =IF(P22=TRUE,E21+F21,) -> 0 | N22: =ISTEXT(D22) -> FALSE | O22: =ISNUMBER(D22) -> FALSE | P22: =OR(N22=TRUE,O22=TRUE) -> FALSE
C23: =IF(P23=TRUE,C22+1,) -> 0 | E23: =IF(P23=TRUE,E22+F22,) -> 0 | N23: =ISTEXT(D23) -> FALSE | O23: =ISNUMBER(D23) -> FALSE | P23: =OR(N23=TRUE,O23=TRUE) -> FALSE
C24: =IF(P24=TRUE,C23+1,) -> 0 | E24: =IF(P24=TRUE,E23+F23,) -> 0 | N24: =ISTEXT(D24) -> FALSE | O24: =ISNUMBER(D24) -> FALSE | P24: =OR(N24=TRUE,O24=TRUE) -> FALSE
C25: =IF(P25=TRUE,C24+1,) -> 0 | E25: =IF(P25=TRUE,E24+F24,) -> 0 | N25: =ISTEXT(D25) -> FALSE | O25: =ISNUMBER(D25) -> FALSE | P25: =OR(N25=TRUE,O25=TRUE) -> FALSE
C26: =IF(P26=TRUE,C25+1,) -> 0 | E26: =IF(P26=TRUE,E25+F25,) -> 0 | N26: =ISTEXT(D26) -> FALSE | O26: =ISNUMBER(D26) -> FALSE | P26: =OR(N26=TRUE,O26=TRUE) -> FALSE
C27: =IF(P27=TRUE,C26+1,) -> 0 | E27: =IF(P27=TRUE,E26+F26,) -> 0 | N27: =ISTEXT(D27) -> FALSE | O27: =ISNUMBER(D27) -> FALSE | P27: =OR(N27=TRUE,O27=TRUE) -> FALSE
C28: =IF(P28=TRUE,C27+1,) -> 0 | E28: =IF(P28=TRUE,E27+F27,) -> 0 | N28: =ISTEXT(D28) -> FALSE | O28: =ISNUMBER(D28) -> FALSE | P28: =OR(N28=TRUE,O28=TRUE) -> FALSE
... C99: =IF(P99=TRUE,C98+1,) -> 0 | E99: =IF(P99=TRUE,E98+F98,) -> 0 | N99: =ISTEXT(D99) -> FALSE | O99: =ISNUMBER(D99) -> FALSE | P99: =OR(N99=TRUE,O99=TRUE) -> FALSE

Sheet DI - Discapacidad
D2: Diseño de registro de datos fiscales y personales
D3: ='CONTROL DE VERSIONES'!G68 -> IRPF 2025
D4: Discapacidad
C5: =IF(P5=TRUE,C4+1,) -> 0
C6: =IF(P6=TRUE,C5+1,) -> 0
C7: Este concepto de datos fiscales incluye los datos por discapacidad con origen en el Modelo 990
C9: Nº | D9: Nombre | E9: Posición | F9: Longitud | G9: Descripción
C10: =IF(P10=TRUE,1,) -> 1 | D10: Tipo | E10: =IF(P10=TRUE,1,) -> 1 | F10: 1 | G10: Tipo de registro = '2' | N10: =ISTEXT(D10) -> TRUE | O10: =ISNUMBER(D10) -> FALSE | P10: =OR(N10=TRUE,O10=TRUE) -> TRUE
C11: =IF(P11=TRUE,C10+1,) -> 2 | D11: Código | E11: =IF(P11=TRUE,E10+F10,) -> 2 | F11: 7 | G11: 'DInnnnn' Donde 'DInnnnn' será siempre igual a 'DI00001' | N11: =ISTEXT(D11) -> TRUE | O11: =ISNUMBER(D11) -> FALSE | P11: =OR(N11=TRUE,O11=TRUE) -> TRUE
C12: =IF(P12=TRUE,C11+1,) -> 3 | D12: NIF del declarante | E12: =IF(P12=TRUE,E11+F11,) -> 9 | F12: 9 | N12: =ISTEXT(D12) -> TRUE | O12: =ISNUMBER(D12) -> FALSE | P12: =OR(N12=TRUE,O12=TRUE) -> TRUE
C13: =IF(P13=TRUE,C12+1,) -> 4 | D13: Nombre del declarante | E13: =IF(P13=TRUE,E12+F12,) -> 18 | F13: 40 | N13: =ISTEXT(D13) -> TRUE | O13: =ISNUMBER(D13) -> FALSE | P13: =OR(N13=TRUE,O13=TRUE) -> TRUE
C14: =IF(P14=TRUE,C13+1,) -> 5 | D14: Grado de discapacidad | E14: =IF(P14=TRUE,E13+F13,) -> 58 | F14: 3 | N14: =ISTEXT(D14) -> TRUE | O14: =ISNUMBER(D14) -> FALSE | P14: =OR(N14=TRUE,O14=TRUE) -> TRUE
C15: =IF(P15=TRUE,C14+1,) -> 6 | D15: Necesidad de ayuda de terceras personas | E15: =IF(P15=TRUE,E14+F14,) -> 61 | F15: 1 | G15: " " - NO "S" - SI | N15: =ISTEXT(D15) -> TRUE | O15: =ISNUMBER(D15) -> FALSE | P15: =OR(N15=TRUE,O15=TRUE) -> TRUE
C16: =IF(P16=TRUE,C15+1,) -> 7 | D16: Movilidad reducida | E16: =IF(P16=TRUE,E15+F15,) -> 62 | F16: 1 | G16: " " - NO "S" - SI | N16: =ISTEXT(D16) -> TRUE | O16: =ISNUMBER(D16) -> FALSE | P16: =OR(N16=TRUE,O16=TRUE) -> TRUE
C17: =IF(P17=TRUE,C16+1,) -> 0 | E17: =IF(P17=TRUE,E16+F16,) -> 0 | N17: =ISTEXT(D17) -> FALSE | O17: =ISNUMBER(D17) -> FALSE | P17: =OR(N17=TRUE,O17=TRUE) -> FALSE
C18: =IF(P18=TRUE,C17+1,) -> 0 | E18: =IF(P18=TRUE,E17+F17,) -> 0 | N18: =ISTEXT(D18) -> FALSE | O18: =ISNUMBER(D18) -> FALSE | P18: =OR(N18=TRUE,O18=TRUE) -> FALSE
C19: =IF(P19=TRUE,C18+1,) -> 0 | E19: =IF(P19=TRUE,E18+F18,) -> 0 | N19: =ISTEXT(D19) -> FALSE | O19: =ISNUMBER(D19) -> FALSE | P19: =OR(N19=TRUE,O19=TRUE) -> FALSE
C20: =IF(P20=TRUE,C19+1,) -> 0 | E20: =IF(P20=TRUE,E19+F19,) -> 0 | N20: =ISTEXT(D20) -> FALSE | O20: =ISNUMBER(D20) -> FALSE | P20: =OR(N20=TRUE,O20=TRUE) -> FALSE
C21: =IF(P21=TRUE,C20+1,) -> 0 | E21: =IF(P21=TRUE,E20+F20,) -> 0 | N21: =ISTEXT(D21) -> FALSE | O21: =ISNUMBER(D21) -> FALSE | P21: =OR(N21=TRUE,O21=TRUE) -> FALSE
C22: =IF(P22=TRUE,C21+1,) -> 0 | E22: =IF(P22=TRUE,E21+F21,) -> 0 | N22: =ISTEXT(D22) -> FALSE | O22: =ISNUMBER(D22) -> FALSE | P22: =OR(N22=TRUE,O22=TRUE) -> FALSE
C23: =IF(P23=TRUE,C22+1,) -> 0 | E23: =IF(P23=TRUE,E22+F22,) -> 0 | N23: =ISTEXT(D23) -> FALSE | O23: =ISNUMBER(D23) -> FALSE | P23: =OR(N23=TRUE,O23=TRUE) -> FALSE
C24: =IF(P24=TRUE,C23+1,) -> 0 | E24: =IF(P24=TRUE,E23+F23,) -> 0 | N24: =ISTEXT(D24) -> FALSE | O24: =ISNUMBER(D24) -> FALSE | P24: =OR(N24=TRUE,O24=TRUE) -> FALSE
C25: =IF(P25=TRUE,C24+1,) -> 0 | E25: =IF(P25=TRUE,E24+F24,) -> 0 | N25: =ISTEXT(D25) -> FALSE | O25: =ISNUMBER(D25) -> FALSE | P25: =OR(N25=TRUE,O25=TRUE) -> FALSE
C26: =IF(P26=TRUE,C25+1,) -> 0 | E26: =IF(P26=TRUE,E25+F25,) -> 0 | N26: =ISTEXT(D26) -> FALSE | O26: =ISNUMBER(D26) -> FALSE | P26: =OR(N26=TRUE,O26=TRUE) -> FALSE
C27: =IF(P27=TRUE,C26+1,) -> 0 | E27: =IF(P27=TRUE,E26+F26,) -> 0 | N27: =ISTEXT(D27) -> FALSE | O27: =ISNUMBER(D27) -> FALSE | P27: =OR(N27=TRUE,O27=TRUE) -> FALSE
C28: =IF(P28=TRUE,C27+1,) -> 0 | E28: =IF(P28=TRUE,E27+F27,) -> 0 | N28: =ISTEXT(D28) -> FALSE | O28: =ISNUMBER(D28) -> FALSE | P28: =OR(N28=TRUE,O28=TRUE) -> FALSE
... C99: =IF(P99=TRUE,C98+1,) -> 0 | E99: =IF(P99=TRUE,E98+F98,) -> 0 | N99: =ISTEXT(D99) -> FALSE | O99: =ISNUMBER(D99) -> FALSE | P99: =OR(N99=TRUE,O99=TRUE) -> FALSE

Sheet RTA - Rdto. trabajo mod 190
D2: Diseño de registro de datos fiscales y personales
D3: ='CONTROL DE VERSIONES'!G68 -> IRPF 2025
D4: Rendimientos del trabajo del modelo 190
C5: =IF(P5=TRUE,C4+1,) -> 0
C6: =IF(P6=TRUE,C5+1,) -> 0
C7: Este concepto de datos fiscales incluye los rendimientos del trabajo del Modelo 190
C9: Nº | D9: Nombre | E9: Posición | F9: Longitud | G9: Descripción
C10: =IF(P10=TRUE,1,) -> 1 | D10: Tipo | E10: =IF(P10=TRUE,1,) -> 1 | F10: 1 | G10: Tipo de registro = '2' | N10: =ISTEXT(D10) -> TRUE | O10: =ISNUMBER(D10) -> FALSE | P10: =OR(N10=TRUE,O10=TRUE) -> TRUE
C11: =IF(P11=TRUE,C10+1,) -> 2 | D11: Código concepto | E11: =IF(P11=TRUE,E10+F10,) -> 2 | F11: 7 | G11: RTAnnnn' Donde nnnn es el número del registro de este tipo contenido en el fichero de datos fiscales. | N11: =ISTEXT(D11) -> TRUE | O11: =ISNUMBER(D11) -> FALSE | P11: =OR(N11=TRUE,O11=TRUE) -> TRUE
C12: =IF(P12=TRUE,C11+1,) -> 3 | D12: NIF pagador | E12: =IF(P12=TRUE,E11+F11,) -> 9 | F12: 9 | G12: NIF declarante | N12: =ISTEXT(D12) -> TRUE | O12: =ISNUMBER(D12) -> FALSE | P12: =OR(N12=TRUE,O12=TRUE) -> TRUE
C13: =IF(P13=TRUE,C12+1,) -> 4 | D13: Nombre del pagador | E13: =IF(P13=TRUE,E12+F12,) -> 18 | F13: 40 | G13: Razón Social / Apellidos y nombre del declarante | N13: =ISTEXT(D13) -> TRUE | O13: =ISNUMBER(D13) -> FALSE | P13: =OR(N13=TRUE,O13=TRUE) -> TRUE
C14: =IF(P14=TRUE,C13+1,) -> 5 | D14: Clave y Subclave de percepcion | E14: =IF(P14=TRUE,E13+F13,) -> 58 | F14: 3 | G14: Se entregará en cada registro una de las siguientes combinaciones de las claves y subclaves de percepción del modelo 190: ‘A ‘ - Empleados ‘B1‘ - Prestación ‘B2‘ - Prestación ‘B3‘ - Prestación ‘B4‘ - Prestación ‘B99‘ - Prestación ‘C1 ‘ - Desempleo ‘C2 ‘ - Prestación ERE ‘C3 ‘ - Prestación ERTE ‘C4 ‘ - Prestación autónomos ‘C5 ‘ - Subsidio desempleo ‘C6 ‘ - Renta activa inserción ‘C7 ‘ - Otras prestaciones contributivas ‘C8 ‘ - Otras prestaciones no contributivas ‘C9 ‘ - Prestaciones de varios tipos ‘E1‘ - Consejero ‘E2‘ - Consejero ‘E3‘ - Consejero ‘E4‘ - Consejero ‘F1‘ - Cursos, conf. ‘F2‘ - Cursos, conf. ‘F3‘ - Obras lit., art., cient. ‘F4‘ - Obras lit., art., cient. ‘F5‘ - Propiedad intelectual ‘F6‘ - Propiedad intelectual ‘F7‘ - Derechos de autor | N14: =ISTEXT(D14) -> TRUE | O14: =ISNUMBER(D14) -> FALSE | P14: =OR(N14=TRUE,O14=TRUE) -> TRUE
C15: =IF(P15=TRUE,C14+1,) -> 6 | D15: Percepciones dinerarias | E15: =IF(P15=TRUE,E14+F14,) -> 61 | F15: 13 | N15: =ISTEXT(D15) -> TRUE | O15: =ISNUMBER(D15) -> FALSE | P15: =OR(N15=TRUE,O15=TRUE) -> TRUE
C16: =IF(P16=TRUE,C15+1,) -> 7 | D16: Retenciones | E16: =IF(P16=TRUE,E15+F15,) -> 74 | F16: 13 | N16: =ISTEXT(D16) -> TRUE | O16: =ISNUMBER(D16) -> FALSE | P16: =OR(N16=TRUE,O16=TRUE) -> TRUE
C17: =IF(P17=TRUE,C16+1,) -> 8 | D17: Retribuciones en especie | E17: =IF(P17=TRUE,E16+F16,) -> 87 | F17: 13 | G17: Campo calculado de acuerdo a la siguiente fórmula: Retribuciones en Especie = Valoración (de la percepción en especie) declarada en el modelo + Ingresos a cuenta efectuados – Ingresos a cuenta repercutidos. | N17: =ISTEXT(D17) -> TRUE | O17: =ISNUMBER(D17) -> FALSE | P17: =OR(N17=TRUE,O17=TRUE) -> TRUE
C18: =IF(P18=TRUE,C17+1,) -> 9 | D18: Valoración | E18: =IF(P18=TRUE,E17+F17,) -> 100 | F18: 13 | N18: =ISTEXT(D18) -> TRUE | O18: =ISNUMBER(D18) -> FALSE | P18: =OR(N18=TRUE,O18=TRUE) -> TRUE
C19: =IF(P19=TRUE,C18+1,) -> 10 | D19: Ingresos a cuenta efectuados | E19: =IF(P19=TRUE,E18+F18,) -> 113 | F19: 13 | G19: Ingresos a cuenta efectuados de las percepciones en especie | N19: =ISTEXT(D19) -> TRUE | O19: =ISNUMBER(D19) -> FALSE | P19: =OR(N19=TRUE,O19=TRUE) -> TRUE
C20: =IF(P20=TRUE,C19+1,) -> 11 | D20: Ingresos a cuenta repercutidos | E20: =IF(P20=TRUE,E19+F19,) -> 126 | F20: 13 | G20: Ingresos a cuenta repercutidos de las percepciones en especie | N20: =ISTEXT(D20) -> TRUE | O20: =ISNUMBER(D20) -> FALSE | P20: =OR(N20=TRUE,O20=TRUE) -> TRUE
C21: =IF(P21=TRUE,C20+1,) -> 12 | D21: Gastos deducibles | E21: =IF(P21=TRUE,E20+F20,) -> 139 | F21: 13 | N21: =ISTEXT(D21) -> TRUE | O21: =ISNUMBER(D21) -> FALSE | P21: =OR(N21=TRUE,O21=TRUE) -> TRUE
C22: =IF(P22=TRUE,C21+1,) -> 13 | D22: Reducciones aplicables | E22: =IF(P22=TRUE,E21+F21,) -> 152 | F22: 13 | N22: =ISTEXT(D22) -> TRUE | O22: =ISNUMBER(D22) -> FALSE | P22: =OR(N22=TRUE,O22=TRUE) -> TRUE
C23: =IF(P23=TRUE,C22+1,) -> 14 | D23: Retribucion dineraria por Incapacidad Laboral | E23: =IF(P23=TRUE,E22+F22,) -> 165 | F23: 13 | N23: =ISTEXT(D23) -> TRUE | O23: =ISNUMBER(D23) -> FALSE | P23: =OR(N23=TRUE,O23=TRUE) -> TRUE
C24: =IF(P24=TRUE,C23+1,) -> 15 | D24: Retencion Incapacidad Laboral | E24: =IF(P24=TRUE,E23+F23,) -> 178 | F24: 13 | N24: =ISTEXT(D24) -> TRUE | O24: =ISNUMBER(D24) -> FALSE | P24: =OR(N24=TRUE,O24=TRUE) -> TRUE
C25: =IF(P25=TRUE,C24+1,) -> 16 | D25: Retribucion en especie Incapacidad Laboral | E25: =IF(P25=TRUE,E24+F24,) -> 191 | F25: 13 | G25: Campo calculado de acuerdo a la siguiente fórmula: Retribuciones en Especie = Valoración (de la percepción en especie) declarada IL en el modelo + Ingresos a cuenta efectuados IL – Ingresos a cuenta repercutidos IL. | N25: =ISTEXT(D25) -> TRUE | O25: =ISNUMBER(D25) -> FALSE | P25: =OR(N25=TRUE,O25=TRUE) -> TRUE
C26: =IF(P26=TRUE,C25+1,) -> 17 | D26: Valoracion Incapacidad Laboral | E26: =IF(P26=TRUE,E25+F25,) -> 204 | F26: 13 | N26: =ISTEXT(D26) -> TRUE | O26: =ISNUMBER(D26) -> FALSE | P26: =OR(N26=TRUE,O26=TRUE) -> TRUE
C27: =IF(P27=TRUE,C26+1,) -> 18 | D27: Ingreso a cuenta Incapacidad Laboral | E27: =IF(P27=TRUE,E26+F26,) -> 217 | F27: 13 | N27: =ISTEXT(D27) -> TRUE | O27: =ISNUMBER(D27) -> FALSE | P27: =OR(N27=TRUE,O27=TRUE) -> TRUE
C28: =IF(P28=TRUE,C27+1,) -> 19 | D28: Ingresos a cuenta repercutidos por Incapacidad Laboral | E28: =IF(P28=TRUE,E27+F27,) -> 230 | F28: 13 | N28: =ISTEXT(D28) -> TRUE | O28: =ISNUMBER(D28) -> FALSE | P28: =OR(N28=TRUE,O28=TRUE) -> TRUE
C29: =IF(P29=TRUE,C28+1,) -> 20 | D29: Movilidad geografica | E29: =IF(P29=TRUE,E28+F28,) -> 243 | F29: 1 | G29: Valores posibles: '0' - NO '1' - SI | N29: =ISTEXT(D29) -> TRUE | O29: =ISNUMBER(D29) -> FALSE | P29: =OR(N29=TRUE,O29=TRUE) -> TRUE
C30: =IF(P30=TRUE,C29+1,) -> 21 | D30: Discapacidad | E30: =IF(P30=TRUE,E29+F29,) -> 244 | F30: 1 | G30: Valores posibles: ‘0’ - No padece discapacidad o discapacidad < 33%, ‘1’ - Discapacidad ≥ 33% o < 65%. ‘2’ - Discapacidad ≥ 33% o < 65% y necesita ayuda 3ª persona. ‘3’ - Discapacidad ≥ 65%. | N30: =ISTEXT(D30) -> TRUE | O30: =ISNUMBER(D30) -> FALSE | P30: =OR(N30=TRUE,O30=TRUE) -> TRUE
C31: =IF(P31=TRUE,C30+1,) -> 22 | D31: Marca percepciones FOGASA | E31: =IF(P31=TRUE,E30+F30,) -> 245 | F31: 1 | G31: Pago efectuado por el Fondo de Garantía Salarial (FOGASA) Valores posibles: 'S' - SI 'N' - NO | N31: =ISTEXT(D31) -> TRUE | O31: =ISNUMBER(D31) -> FALSE | P31: =OR(N31=TRUE,O31=TRUE) -> TRUE
C32: =IF(P32=TRUE,C31+1,) -> 23 | D32: Marca especie | E32: =IF(P32=TRUE,E31+F31,) -> 246 | F32: 1 | G32: Valores posibles: '1' - SI '0' - NO | N32: =ISTEXT(D32) -> TRUE | O32: =ISNUMBER(D32) -> FALSE | P32: =OR(N32=TRUE,O32=TRUE) -> TRUE
C33: =IF(P33=TRUE,C32+1,) -> 24 | D33: Subtipos B01 | E33: =IF(P33=TRUE,E32+F32,) -> 247 | F33: 5 | N33: =ISTEXT(D33) -> TRUE | O33: =ISNUMBER(D33) -> FALSE | P33: =OR(N33=TRUE,O33=TRUE) -> TRUE
C34: =IF(P34=TRUE,C33+1,) -> 25 | D34: Obtenidos Gestión Fondos | E34: =IF(P34=TRUE,E33+F33,) -> 252 | F34: 1 | G34: Valores posibles: '1' - SI '0' - NO | N34: =ISTEXT(D34) -> TRUE | O34: =ISNUMBER(D34) -> FALSE | P34: =OR(N34=TRUE,O34=TRUE) -> TRUE
C35: =IF(P35=TRUE,C34+1,) -> 0 | E35: =IF(P35=TRUE,E34+F34,) -> 0 | N35: =ISTEXT(D35) -> FALSE | O35: =ISNUMBER(D35) -> FALSE | P35: =OR(N35=TRUE,O35=TRUE) -> FALSE
C36: =IF(P36=TRUE,C35+1,) -> 0 | E36: =IF(P36=TRUE,E35+F35,) -> 0 | N36: =ISTEXT(D36) -> FALSE | O36: =ISNUMBER(D36) -> FALSE | P36: =OR(N36=TRUE,O36=TRUE) -> FALSE
C37: =IF(P37=TRUE,C36+1,) -> 0 | E37: =IF(P37=TRUE,E36+F36,) -> 0 | N37: =ISTEXT(D37) -> FALSE | O37: =ISNUMBER(D37) -> FALSE | P37: =OR(N37=TRUE,O37=TRUE) -> FALSE
C38: =IF(P38=TRUE,C37+1,) -> 0 | E38: =IF(P38=TRUE,E37+F37,) -> 0 | N38: =ISTEXT(D38) -> FALSE | O38: =ISNUMBER(D38) -> FALSE | P38: =OR(N38=TRUE,O38=TRUE) -> FALSE
C39: =IF(P39=TRUE,C38+1,) -> 0 | E39: =IF(P39=TRUE,E38+F38,) -> 0 | N39: =ISTEXT(D39) -> FALSE | O39: =ISNUMBER(D39) -> FALSE | P39: =OR(N39=TRUE,O39=TRUE) -> FALSE
C40: =IF(P40=TRUE,C39+1,) -> 0 | E40: =IF(P40=TRUE,E39+F39,) -> 0 | N40: =ISTEXT(D40) -> FALSE | O40: =ISNUMBER(D40) -> FALSE | P40: =OR(N40=TRUE,O40=TRUE) -> FALSE
C41: =IF(P41=TRUE,C40+1,) -> 0 | E41: =IF(P41=TRUE,E40+F40,) -> 0 | N41: =ISTEXT(D41) -> FALSE | O41: =ISNUMBER(D41) -> FALSE | P41: =OR(N41=TRUE,O41=TRUE) -> FALSE
C42: =IF(P42=TRUE,C41+1,) -> 0 | E42: =IF(P42=TRUE,E41+F41,) -> 0 | N42: =ISTEXT(D42) -> FALSE | O42: =ISNUMBER(D42) -> FALSE | P42: =OR(N42=TRUE,O42=TRUE) -> FALSE
...

Sheet RTD - Rentas exentas
D2: Diseño de registro de datos fiscales y personales
D3: ='CONTROL DE VERSIONES'!G68 -> IRPF 2025
D4: Rentas exentas
C5: =IF(P5=TRUE,C4+1,) -> 0
C6: =IF(P6=TRUE,C5+1,) -> 0
C7: Este concepto de datos fiscales incluye las rentas exentas con origen en el Modelo 190. - La subclave L29 (Prestaciones económicas en concepto de ingreso mínimo vital - IMV) se remite siempre. Dichas cantidades están exentas de tributación en IRPF. No obstante, el artículo 33 del RDLey 20/2020 establece la obligación de presentar anualmente declaración de IRPF para todos los beneficiarios del IMV integrantes de la unidad de convivencia. - Las subclaves L22 y L28 solo se remiten si el importe conjunto percibido de las subclave L22, L28 y/o L29 supera el límite máximo anual que establece el artículo 7. letra y) de la LIRPF como cuantía exenta de tributación, fijada en 1,5 veces el IPREM (12.159,42 € para 2022) (indicador público de rentas de efectos múltiples), el exceso deberá consignarse en la declaración de IRPF, teniendo la consideración de rendimiento de trabajo personal.
C9: Nº | D9: Nombre | E9: Posición | F9: Longitud | G9: Descripción
C10: =IF(P10=TRUE,1,) -> 1 | D10: Tipo | E10: =IF(P10=TRUE,1,) -> 1 | F10: 1 | G10: Tipo de registro = '2' | N10: =ISTEXT(D10) -> TRUE | O10: =ISNUMBER(D10) -> FALSE | P10: =OR(N10=TRUE,O10=TRUE) -> TRUE
C11: =IF(P11=TRUE,C10+1,) -> 2 | D11: Código | E11: =IF(P11=TRUE,E10+F10,) -> 2 | F11: 7 | G11: 'RTDnnnn' Donde nnnn es el número del registro de este tipo contenido en el fichero de datos fiscales. | N11: =ISTEXT(D11) -> TRUE | O11: =ISNUMBER(D11) -> FALSE | P11: =OR(N11=TRUE,O11=TRUE) -> TRUE
C12: =IF(P12=TRUE,C11+1,) -> 3 | D12: NIF del pagador | E12: =IF(P12=TRUE,E11+F11,) -> 9 | F12: 9 | N12: =ISTEXT(D12) -> TRUE | O12: =ISNUMBER(D12) -> FALSE | P12: =OR(N12=TRUE,O12=TRUE) -> TRUE
C13: =IF(P13=TRUE,C12+1,) -> 4 | D13: Nombre del pagador | E13: =IF(P13=TRUE,E12+F12,) -> 18 | F13: 40 | N13: =ISTEXT(D13) -> TRUE | O13: =ISNUMBER(D13) -> FALSE | P13: =OR(N13=TRUE,O13=TRUE) -> TRUE
C14: =IF(P14=TRUE,C13+1,) -> 5 | D14: Clave y subclave | E14: =IF(P14=TRUE,E13+F13,) -> 58 | F14: 3 | G14: Clave(1) + Subclave (2) Claves: 'L05' - Indemnizaciones 'L10' - Becas 'L22' - Otras ayudas de CCAA y EELL de carácter social 'L25' - Ayuda empresas para guarderías 'L26' - Ayuda guarderías a sus empleados 'L27' - Prestaciones maternidad o paternidad 'L28' - Renta mínima de inserción 'L29' - Ingreso mínimo vital | N14: =ISTEXT(D14) -> TRUE | O14: =ISNUMBER(D14) -> FALSE | P14: =OR(N14=TRUE,O14=TRUE) -> TRUE
C15: =IF(P16=TRUE,C14+1,) -> 6 | D15: Retribución dineraria | E15: =IF(P16=TRUE,E14+F14,) -> 61 | F15: 13
C16: =IF(P16=TRUE,C15+1,) -> 7 | D16: Retribución en especie | E16: 74 | F16: 13 | G16: (Valoración dda. + Ing cat efec. - ing.cta repercutido) Campo calculado de acuerdo a la siguiente fórmula: Retribuciones en Especie = Valoración (de la percepción en especie) declarada en el modelo + Ingresos a cuenta efectuados – Ingresos a cuenta repercutidos. | N16: =ISTEXT(D15) -> TRUE | O16: =ISNUMBER(D15) -> FALSE | P16: =OR(N16=TRUE,O16=TRUE) -> TRUE
C17: 8 | D17: Gastos deducibles | E17: 87 | F17: 13 | N17: =ISTEXT(D17) -> TRUE | O17: =ISNUMBER(D17) -> FALSE | P17: =OR(N17=TRUE,O17=TRUE) -> TRUE
C18: =IF(P18=TRUE,C17+1,) -> 0 | E18: =IF(P18=TRUE,E17+F17,) -> 0 | N18: =ISTEXT(D18) -> FALSE | O18: =ISNUMBER(D18) -> FALSE | P18: =OR(N18=TRUE,O18=TRUE) -> FALSE
C19: =IF(P19=TRUE,C18+1,) -> 0 | E19: =IF(P19=TRUE,E18+F18,) -> 0 | N19: =ISTEXT(D19) -> FALSE | O19: =ISNUMBER(D19) -> FALSE | P19: =OR(N19=TRUE,O19=TRUE) -> FALSE
C20: =IF(P20=TRUE,C19+1,) -> 0 | E20: =IF(P20=TRUE,E19+F19,) -> 0 | N20: =ISTEXT(D20) -> FALSE | O20: =ISNUMBER(D20) -> FALSE | P20: =OR(N20=TRUE,O20=TRUE) -> FALSE
C21: =IF(P21=TRUE,C20+1,) -> 0 | E21: =IF(P21=TRUE,E20+F20,) -> 0 | N21: =ISTEXT(D21) -> FALSE | O21: =ISNUMBER(D21) -> FALSE | P21: =OR(N21=TRUE,O21=TRUE) -> FALSE
C22: =IF(P22=TRUE,C21+1,) -> 0 | E22: =IF(P22=TRUE,E21+F21,) -> 0 | N22: =ISTEXT(D22) -> FALSE | O22: =ISNUMBER(D22) -> FALSE | P22: =OR(N22=TRUE,O22=TRUE) -> FALSE
C23: =IF(P23=TRUE,C22+1,) -> 0 | E23: =IF(P23=TRUE,E22+F22,) -> 0 | N23: =ISTEXT(D23) -> FALSE | O23: =ISNUMBER(D23) -> FALSE | P23: =OR(N23=TRUE,O23=TRUE) -> FALSE
C24: =IF(P24=TRUE,C23+1,) -> 0 | E24: =IF(P24=TRUE,E23+F23,) -> 0 | N24: =ISTEXT(D24) -> FALSE | O24: =ISNUMBER(D24) -> FALSE | P24: =OR(N24=TRUE,O24=TRUE) -> FALSE
C25: =IF(P25=TRUE,C24+1,) -> 0 | E25: =IF(P25=TRUE,E24+F24,) -> 0 | N25: =ISTEXT(D25) -> FALSE | O25: =ISNUMBER(D25) -> FALSE | P25: =OR(N25=TRUE,O25=TRUE) -> FALSE
C26: =IF(P26=TRUE,C25+1,) -> 0 | E26: =IF(P26=TRUE,E25+F25,) -> 0 | N26: =ISTEXT(D26) -> FALSE | O26: =ISNUMBER(D26) -> FALSE | P26: =OR(N26=TRUE,O26=TRUE) -> FALSE
C27: =IF(P27=TRUE,C26+1,) -> 0 | E27: =IF(P27=TRUE,E26+F26,) -> 0 | N27: =ISTEXT(D27) -> FALSE | O27: =ISNUMBER(D27) -> FALSE | P27: =OR(N27=TRUE,O27=TRUE) -> FALSE
C28: =IF(P28=TRUE,C27+1,) -> 0 | E28: =IF(P28=TRUE,E27+F27,) -> 0 | N28: =ISTEXT(D28) -> FALSE | O28: =ISNUMBER(D28) -> FALSE | P28: =OR(N28=TRUE,O28=TRUE) -> FALSE
C29: =IF(P29=TRUE,C28+1,) -> 0 | E29: =IF(P29=TRUE,E28+F28,) -> 0 | N29: =ISTEXT(D29) -> FALSE | O29: =ISNUMBER(D29) -> FALSE | P29: =OR(N29=TRUE,O29=TRUE) -> FALSE
... C100: =IF(P100=TRUE,C99+1,) -> 0 | E100: =IF(P100=TRUE,E99+F99,) -> 0 | N100: =ISTEXT(D100) -> FALSE | O100: =ISNUMBER(D100) -> FALSE | P100: =OR(N100=TRUE,O100=TRUE) -> FALSE

Sheet RTB - Premios y Ganancias Patr.
D2: Diseño de registro de datos fiscales y personales
D3: ='CONTROL DE VERSIONES'!G68 -> IRPF 2025
D4: Premios y ganancias patrimoniales
C5: =IF(P5=TRUE,C4+1,) -> 0
C6: =IF(P6=TRUE,C5+1,) -> 0
C7: Este concepto de datos fiscales incluye los premios y ganancias patrimoniales con origen en el Modelo 190
C9: Nº | D9: Nombre | E9: Posición | F9: Longitud | G9: Descripción
C10: =IF(P10=TRUE,1,) -> 1 | D10: Tipo | E10: =IF(P10=TRUE,1,) -> 1 | F10: 1 | G10: Tipo de registro = '2' | N10: =ISTEXT(D10) -> TRUE | O10: =ISNUMBER(D10) -> FALSE | P10: =OR(N10=TRUE,O10=TRUE) -> TRUE
C11: =IF(P11=TRUE,C10+1,) -> 2 | D11: Código | E11: =IF(P11=TRUE,E10+F10,) -> 2 | F11: 7 | G11: 'RTBnnnn' Donde nnnn es el número del registro de este tipo contenido en el fichero de datos fiscales. | N11: =ISTEXT(D11) -> TRUE | O11: =ISNUMBER(D11) -> FALSE | P11: =OR(N11=TRUE,O11=TRUE) -> TRUE
C12: =IF(P12=TRUE,C11+1,) -> 3 | D12: NIF del pagador | E12: =IF(P12=TRUE,E11+F11,) -> 9 | F12: 9 | N12: =ISTEXT(D12) -> TRUE | O12: =ISNUMBER(D12) -> FALSE | P12: =OR(N12=TRUE,O12=TRUE) -> TRUE
C13: =IF(P13=TRUE,C12+1,) -> 4 | D13: Nombre del pagador | E13: =IF(P13=TRUE,E12+F12,) -> 18 | F13: 40 | N13: =ISTEXT(D13) -> TRUE | O13: =ISNUMBER(D13) -> FALSE | P13: =OR(N13=TRUE,O13=TRUE) -> TRUE
C14: =IF(P14=TRUE,C13+1,) -> 5 | D14: Clave y subclave | E14: =IF(P14=TRUE,E13+F13,) -> 58 | F14: 2 | G14: Clave(1) + Subclave (1) Claves: 'K1' - Premios sin fines publicitarios 'K2' - Aprovechamientos forestales 'K3' - Premios con fines publicitarios con retención 'K4' - Premios sin fines publicitarios sin retención 'K5' - Premios con fines publicitarios sin retención | N14: =ISTEXT(D14) -> TRUE | O14: =ISNUMBER(D14) -> FALSE | P14: =OR(N14=TRUE,O14=TRUE) -> TRUE
C15: =IF(P15=TRUE,C14+1,) -> 6 | D15: Retribución dineraria | E15: =IF(P15=TRUE,E14+F14,) -> 60 | F15: 13 | N15: =ISTEXT(D15) -> TRUE | O15: =ISNUMBER(D15) -> FALSE | P15: =OR(N15=TRUE,O15=TRUE) -> TRUE
C16: =IF(P16=TRUE,C15+1,) -> 7 | D16: Retención | E16: =IF(P16=TRUE,E15+F15,) -> 73 | F16: 13 | N16: =ISTEXT(D16) -> TRUE | O16: =ISNUMBER(D16) -> FALSE | P16: =OR(N16=TRUE,O16=TRUE) -> TRUE
C17: =IF(P17=TRUE,C16+1,) -> 8 | D17: Retribución en especie | E17: =IF(P17=TRUE,E16+F16,) -> 86 | F17: 13 | G17: (Valoración dda. + Ing cat efec. - ing.cta repercutido) Campo calculado de acuerdo a la siguiente fórmula: Retribuciones en Especie = Valoración (de la percepción en especie) declarada en el modelo + Ingresos a cuenta efectuados – Ingresos a cuenta repercutidos. | N17: =ISTEXT(D17) -> TRUE | O17: =ISNUMBER(D17) -> FALSE | P17: =OR(N17=TRUE,O17=TRUE) -> TRUE
C18: =IF(P18=TRUE,C17+1,) -> 9 | D18: Valoracion | E18: =IF(P18=TRUE,E17+F17,) -> 99 | F18: 13 | N18: =ISTEXT(D18) -> TRUE | O18: =ISNUMBER(D18) -> FALSE | P18: =OR(N18=TRUE,O18=TRUE) -> TRUE
C19: =IF(P19=TRUE,C18+1,) -> 10 | D19: Ingreso a cta | E19: =IF(P19=TRUE,E18+F18,) -> 112 | F19: 13 | G19: Ingresos a cuenta efectuados de las percepciones en especie | N19: =ISTEXT(D19) -> TRUE | O19: =ISNUMBER(D19) -> FALSE | P19: =OR(N19=TRUE,O19=TRUE) -> TRUE
C20: =IF(P20=TRUE,C19+1,) -> 11 | D20: Ingreso a cta repercutido | E20: =IF(P20=TRUE,E19+F19,) -> 125 | F20: 13 | G20: Ingresos a cuenta repercutidos de las percepciones en especie | N20: =ISTEXT(D20) -> TRUE | O20: =ISNUMBER(D20) -> FALSE | P20: =OR(N20=TRUE,O20=TRUE) -> TRUE
C21: =IF(P21=TRUE,C20+1,) -> 0 | E21: =IF(P21=TRUE,E20+F20,) -> 0 | N21: =ISTEXT(D21) -> FALSE | O21: =ISNUMBER(D21) -> FALSE | P21: =OR(N21=TRUE,O21=TRUE) -> FALSE
C22: =IF(P22=TRUE,C21+1,) -> 0 | E22: =IF(P22=TRUE,E21+F21,) -> 0 | N22: =ISTEXT(D22) -> FALSE | O22: =ISNUMBER(D22) -> FALSE | P22: =OR(N22=TRUE,O22=TRUE) -> FALSE
C23: =IF(P23=TRUE,C22+1,) -> 0 | E23: =IF(P23=TRUE,E22+F22,) -> 0 | N23: =ISTEXT(D23) -> FALSE | O23: =ISNUMBER(D23) -> FALSE | P23: =OR(N23=TRUE,O23=TRUE) -> FALSE
C24: =IF(P24=TRUE,C23+1,) -> 0 | E24: =IF(P24=TRUE,E23+F23,) -> 0 | N24: =ISTEXT(D24) -> FALSE | O24: =ISNUMBER(D24) -> FALSE | P24: =OR(N24=TRUE,O24=TRUE) -> FALSE
C25: =IF(P25=TRUE,C24+1,) -> 0 | E25: =IF(P25=TRUE,E24+F24,) -> 0 | N25: =ISTEXT(D25) -> FALSE | O25: =ISNUMBER(D25) -> FALSE | P25: =OR(N25=TRUE,O25=TRUE) -> FALSE
C26: =IF(P26=TRUE,C25+1,) -> 0 | E26: =IF(P26=TRUE,E25+F25,) -> 0 | N26: =ISTEXT(D26) -> FALSE | O26: =ISNUMBER(D26) -> FALSE | P26: =OR(N26=TRUE,O26=TRUE) -> FALSE
C27: =IF(P27=TRUE,C26+1,) -> 0 | E27: =IF(P27=TRUE,E26+F26,) -> 0 | N27: =ISTEXT(D27) -> FALSE | O27: =ISNUMBER(D27) -> FALSE | P27: =OR(N27=TRUE,O27=TRUE) -> FALSE
C28: =IF(P28=TRUE,C27+1,) -> 0 | E28: =IF(P28=TRUE,E27+F27,) -> 0 | N28: =ISTEXT(D28) -> FALSE | O28: =ISNUMBER(D28) -> FALSE | P28: =OR(N28=TRUE,O28=TRUE) -> FALSE
C29: =IF(P29=TRUE,C28+1,) -> 0 | E29: =IF(P29=TRUE,E28+F28,) -> 0 | N29: =ISTEXT(D29) -> FALSE | O29: =ISNUMBER(D29) -> FALSE | P29: =OR(N29=TRUE,O29=TRUE) -> FALSE
C30: =IF(P30=TRUE,C29+1,) -> 0 | E30: =IF(P30=TRUE,E29+F29,) -> 0 | N30: =ISTEXT(D30) -> FALSE | O30: =ISNUMBER(D30) -> FALSE | P30: =OR(N30=TRUE,O30=TRUE) -> FALSE
C31: =IF(P31=TRUE,C30+1,) -> 0 | E31: =IF(P31=TRUE,E30+F30,) -> 0 | N31: =ISTEXT(D31) -> FALSE | O31: =ISNUMBER(D31) -> FALSE | P31: =OR(N31=TRUE,O31=TRUE) -> FALSE
C32: =IF(P32=TRUE,C31+1,) -> 0 | E32: =IF(P32=TRUE,E31+F31,) -> 0 | N32: =ISTEXT(D32) -> FALSE | O32: =ISNUMBER(D32) -> FALSE | P32: =OR(N32=TRUE,O32=TRUE) -> FALSE
... C99: =IF(P99=TRUE,C98+1,) -> 0 | E99: =IF(P99=TRUE,E98+F98,) -> 0 | N99: =ISTEXT(D99) -> FALSE | O99: =ISNUMBER(D99) -> FALSE | P99: =OR(N99=TRUE,O99=TRUE) -> FALSE

Sheet RTC - Activid. Econom. Mod.190
D2: Diseño de registro de datos fiscales y personales
D3: ='CONTROL DE VERSIONES'!G68 -> IRPF 2025
D4: Actividades Económicas modelo 190
C5: =IF(P5=TRUE,C4+1,) -> 0
C6: =IF(P6=TRUE,C5+1,) -> 0
C7: Este concepto de datos fiscales incluye los datos de Actividades Económicas con origen en el Modelo 190
C9: Nº | D9: Nombre | E9: Posición | F9: Longitud | G9: Descripción
C10: =IF(P10=TRUE,1,) -> 1 | D10: Tipo | E10: =IF(P10=TRUE,1,) -> 1 | F10: 1 | G10: Tipo de registro = '2' | N10: =ISTEXT(D10) -> TRUE | O10: =ISNUMBER(D10) -> FALSE | P10: =OR(N10=TRUE,O10=TRUE) -> TRUE
C11: =IF(P11=TRUE,C10+1,) -> 2 | D11: Código | E11: =IF(P11=TRUE,E10+F10,) -> 2 | F11: 7 | G11: 'RTCnnnn' Donde nnnn es el número del registro de este tipo contenido en el fichero de datos fiscales. | N11: =ISTEXT(D11) -> TRUE | O11: =ISNUMBER(D11) -> FALSE | P11: =OR(N11=TRUE,O11=TRUE) -> TRUE
C12: =IF(P12=TRUE,C11+1,) -> 3 | D12: NIF del pagador | E12: =IF(P12=TRUE,E11+F11,) -> 9 | F12: 9 | N12: =ISTEXT(D12) -> TRUE | O12: =ISNUMBER(D12) -> FALSE | P12: =OR(N12=TRUE,O12=TRUE) -> TRUE
C13: =IF(P13=TRUE,C12+1,) -> 4 | D13: Nombre del pagador | E13: =IF(P13=TRUE,E12+F12,) -> 18 | F13: 40 | N13: =ISTEXT(D13) -> TRUE | O13: =ISNUMBER(D13) -> FALSE | P13: =OR(N13=TRUE,O13=TRUE) -> TRUE
C14: =IF(P14=TRUE,C13+1,) -> 5 | D14: Clave y subclave | E14: =IF(P14=TRUE,E13+F13,) -> 58 | F14: 2 | G14: Clave(1) + Subclave (1) Claves: 'G1' - Activ. Prof. 'G2' - Activ. Prof. 'G3' - Activ. Prof. 'G4' - Activ. Prof. 'G5' - Activ. Prof. 'G6' - Activ. Prof. 'G7' - Activ. Prof. 'G8' - Activ. Prof. 'H1' - Activ. Agric y empresarial en EO 'H2' - Activ. Agric y empresarial en EO 'H3' - Activ. Agric y empresarial en EO 'H4' - Activ. Agric y empresarial en EO 'I1' - Activ. econ. 'I2' - Activ. econ. 'I3' - Activ. econ. 'J' - Der. Imagen | N14: =ISTEXT(D14) -> TRUE | O14: =ISNUMBER(D14) -> FALSE | P14: =OR(N14=TRUE,O14=TRUE) -> TRUE
C15: =IF(P15=TRUE,C14+1,) -> 6 | D15: Retribución dineraria | E15: =IF(P15=TRUE,E14+F14,) -> 60 | F15: 13 | N15: =ISTEXT(D15) -> TRUE | O15: =ISNUMBER(D15) -> FALSE | P15: =OR(N15=TRUE,O15=TRUE) -> TRUE
C16: =IF(P16=TRUE,C15+1,) -> 7 | D16: Retención | E16: =IF(P16=TRUE,E15+F15,) -> 73 | F16: 13 | N16: =ISTEXT(D16) -> TRUE | O16: =ISNUMBER(D16) -> FALSE | P16: =OR(N16=TRUE,O16=TRUE) -> TRUE
C17: =IF(P17=TRUE,C16+1,) -> 8 | D17: Retribución en especie | E17: =IF(P17=TRUE,E16+F16,) -> 86 | F17: 13 | G17: (Valoración dda. + Ing cat efec. - ing.cta repercutido) Campo calculado de acuerdo a la siguiente fórmula: Retribuciones en Especie = Valoración (de la percepción en especie) declarada en el modelo + Ingresos a cuenta efectuados – Ingresos a cuenta repercutidos. | N17: =ISTEXT(D17) -> TRUE | O17: =ISNUMBER(D17) -> FALSE | P17: =OR(N17=TRUE,O17=TRUE) -> TRUE
C18: =IF(P18=TRUE,C17+1,) -> 9 | D18: Valoracion | E18: =IF(P18=TRUE,E17+F17,) -> 99 | F18: 13 | N18: =ISTEXT(D18) -> TRUE | O18: =ISNUMBER(D18) -> FALSE | P18: =OR(N18=TRUE,O18=TRUE) -> TRUE
C19: =IF(P19=TRUE,C18+1,) -> 10 | D19: Ingreso a cta | E19: =IF(P19=TRUE,E18+F18,) -> 112 | F19: 13 | G19: Ingresos a cuenta efectuados de las percepciones en especie | N19: =ISTEXT(D19) -> TRUE | O19: =ISNUMBER(D19) -> FALSE | P19: =OR(N19=TRUE,O19=TRUE) -> TRUE
C20: =IF(P20=TRUE,C19+1,) -> 11 | D20: Ingreso a cta repercutido | E20: =IF(P20=TRUE,E19+F19,) -> 125 | F20: 13 | G20: Ingresos a cuenta repercutidos de las percepciones en especie | N20: =ISTEXT(D20) -> TRUE | O20: =ISNUMBER(D20) -> FALSE | P20: =OR(N20=TRUE,O20=TRUE) -> TRUE
C21: =IF(P21=TRUE,C20+1,) -> 12 | D21: Reducciones aplicables | E21: =IF(P21=TRUE,E20+F20,) -> 138 | F21: 13 | N21: =ISTEXT(D21) -> TRUE | O21: =ISNUMBER(D21) -> FALSE | P21: =OR(N21=TRUE,O21=TRUE) -> TRUE
C22: =IF(P22=TRUE,C21+1,) -> 0 | E22: =IF(P22=TRUE,E21+F21,) -> 0 | N22: =ISTEXT(D22) -> FALSE | O22: =ISNUMBER(D22) -> FALSE | P22: =OR(N22=TRUE,O22=TRUE) -> FALSE
C23: =IF(P23=TRUE,C22+1,) -> 0 | E23: =IF(P23=TRUE,E22+F22,) -> 0 | N23: =ISTEXT(D23) -> FALSE | O23: =ISNUMBER(D23) -> FALSE | P23: =OR(N23=TRUE,O23=TRUE) -> FALSE
C24: =IF(P24=TRUE,C23+1,) -> 0 | E24: =IF(P24=TRUE,E23+F23,) -> 0 | N24: =ISTEXT(D24) -> FALSE | O24: =ISNUMBER(D24) -> FALSE | P24: =OR(N24=TRUE,O24=TRUE) -> FALSE
C25: =IF(P25=TRUE,C24+1,) -> 0 | E25: =IF(P25=TRUE,E24+F24,) -> 0 | N25: =ISTEXT(D25) -> FALSE | O25: =ISNUMBER(D25) -> FALSE | P25: =OR(N25=TRUE,O25=TRUE) -> FALSE
C26: =IF(P26=TRUE,C25+1,) -> 0 | E26: =IF(P26=TRUE,E25+F25,) -> 0 | N26: =ISTEXT(D26) -> FALSE | O26: =ISNUMBER(D26) -> FALSE | P26: =OR(N26=TRUE,O26=TRUE) -> FALSE
C27: =IF(P27=TRUE,C26+1,) -> 0 | E27: =IF(P27=TRUE,E26+F26,) -> 0 | N27: =ISTEXT(D27) -> FALSE | O27: =ISNUMBER(D27) -> FALSE | P27: =OR(N27=TRUE,O27=TRUE) -> FALSE
C28: =IF(P28=TRUE,C27+1,) -> 0 | E28: =IF(P28=TRUE,E27+F27,) -> 0 | N28: =ISTEXT(D28) -> FALSE | O28: =ISNUMBER(D28) -> FALSE | P28: =OR(N28=TRUE,O28=TRUE) -> FALSE
C29: =IF(P29=TRUE,C28+1,) -> 0 | E29: =IF(P29=TRUE,E28+F28,) -> 0 | N29: =ISTEXT(D29) -> FALSE | O29: =ISNUMBER(D29) -> FALSE | P29: =OR(N29=TRUE,O29=TRUE) -> FALSE
C30: =IF(P30=TRUE,C29+1,) -> 0 | E30: =IF(P30=TRUE,E29+F29,) -> 0 | N30: =ISTEXT(D30) -> FALSE | O30: =ISNUMBER(D30) -> FALSE | P30: =OR(N30=TRUE,O30=TRUE) -> FALSE
C31: =IF(P31=TRUE,C30+1,) -> 0 | E31: =IF(P31=TRUE,E30+F30,) -> 0 | N31: =ISTEXT(D31) -> FALSE | O31: =ISNUMBER(D31) -> FALSE | P31: =OR(N31=TRUE,O31=TRUE) -> FALSE
C32: =IF(P32=TRUE,C31+1,) -> 0 | E32: =IF(P32=TRUE,E31+F31,) -> 0 | N32: =ISTEXT(D32) -> FALSE | O32: =ISNUMBER(D32) -> FALSE | P32: =OR(N32=TRUE,O32=TRUE) -> FALSE
C33: =IF(P33=TRUE,C32+1,) -> 0 | E33: =IF(P33=TRUE,E32+F32,) -> 0 | N33: =ISTEXT(D33) -> FALSE | O33: =ISNUMBER(D33) -> FALSE | P33: =OR(N33=TRUE,O33=TRUE) -> FALSE
... C99: =IF(P99=TRUE,C98+1,) -> 0 | E99: =IF(P99=TRUE,E98+F98,) -> 0 | N99: =ISTEXT(D99) -> FALSE | O99: =ISNUMBER(D99) -> FALSE | P99: =OR(N99=TRUE,O99=TRUE) -> FALSE

Sheet AA - Devengo ant. al ejercicio
D2: Diseño de registro de datos fiscales y personales
D3: ='CONTROL DE VERSIONES'!G68 -> IRPF 2025
D4: Rdtos. del trabajo, Act. Económicas, Premios, Ganancias Patrimoniales e Imputaciones de Renta, con ejercicio de devengo anterior a 2025
C5: =IF(P5=TRUE,C4+1,) -> 0
C6: =IF(P6=TRUE,C5+1,) -> 0
C7: Información procedente del modelo de declaración informativa 190: “Retenciones e ingresos a cuenta del Impuesto sobre la Renta de las Personas Físicas. Rendimientos del trabajo y de actividades económicas, premios y determinadas ganancias patrimoniales e imputaciones de renta. Resumen anual”. Con ejercicio de devengo anterior a 2025.
C9: Nº | D9: Nombre | E9: Posición | F9: Longitud | G9: Descripción
C10: =IF(P10=TRUE,1,) -> 1 | D10: Tipo | E10: =IF(P10=TRUE,1,) -> 1 | F10: 1 | G10: Tipo de registro = '2' | N10: =ISTEXT(D10) -> TRUE | O10: =ISNUMBER(D10) -> FALSE | P10: =OR(N10=TRUE,O10=TRUE) -> TRUE
C11: =IF(P11=TRUE,C10+1,) -> 2 | D11: Código | E11: =IF(P11=TRUE,E10+F10,) -> 2 | F11: 7 | G11: 'AAnnnnn' Donde nnnn es el número del registro de este tipo contenido en el fichero de datos fiscales. | N11: =ISTEXT(D11) -> TRUE | O11: =ISNUMBER(D11) -> FALSE | P11: =OR(N11=TRUE,O11=TRUE) -> TRUE
C12: =IF(P12=TRUE,C11+1,) -> 3 | D12: NIF del Pagador | E12: =IF(P12=TRUE,E11+F11,) -> 9 | F12: 9 | N12: =ISTEXT(D12) -> TRUE | O12: =ISNUMBER(D12) -> FALSE | P12: =OR(N12=TRUE,O12=TRUE) -> TRUE
C13: =IF(P13=TRUE,C12+1,) -> 4 | D13: Nombre del Pagador | E13: =IF(P13=TRUE,E12+F12,) -> 18 | F13: 40 | N13: =ISTEXT(D13) -> TRUE | O13: =ISNUMBER(D13) -> FALSE | P13: =OR(N13=TRUE,O13=TRUE) -> TRUE
C14: =IF(P14=TRUE,C13+1,) -> 5 | D14: Ejercicio del devengo | E14: =IF(P14=TRUE,E13+F13,) -> 58 | F14: 4 | N14: =ISTEXT(D14) -> TRUE | O14: =ISNUMBER(D14) -> FALSE | P14: =OR(N14=TRUE,O14=TRUE) -> TRUE
C15: =IF(P15=TRUE,C14+1,) -> 6 | D15: Clave | E15: =IF(P15=TRUE,E14+F14,) -> 62 | F15: 3 | G15: Clave (1) + Sub clave (2) Claves: ‘A‘ - Empleado ‘B2‘ - Prestación ‘B*‘ - Pensionista ‘C‘ - Desempleado ‘D‘ - Desemp. P. U. ‘E*‘ - Consejero ‘F*‘ - Cursos,conf. ‘G*‘ - Activ. prof. ‘H*‘ - Activ. Agric. y empresariales en EO ‘I*‘ - Activ. econ. ‘J‘ - Der. De imagen ‘K1‘ - Premios ‘K2‘ - Aprovechamientos forestales ‘K3‘ - Premios ‘L05‘ - Indemnizaciones ‘L10’ - Becas ‘L25’ - Ayuda empresas para guarderías ‘L26’ - Ayuda guarderías a sus empleados ‘L27’ - Prestaciones maternidad | N15: =ISTEXT(D15) -> TRUE | O15: =ISNUMBER(D15) -> FALSE | P15: =OR(N15=TRUE,O15=TRUE) -> TRUE
C16: =IF(P16=TRUE,C15+1,) -> 7 | D16: Retribuciones Dineraria | E16: =IF(P16=TRUE,E15+F15,) -> 65 | F16: 13 | N16: =ISTEXT(D16) -> TRUE | O16: =ISNUMBER(D16) -> FALSE | P16: =OR(N16=TRUE,O16=TRUE) -> TRUE
C17: =IF(P17=TRUE,C16+1,) -> 8 | D17: Retención | E17: =IF(P17=TRUE,E16+F16,) -> 78 | F17: 13 | N17: =ISTEXT(D17) -> TRUE | O17: =ISNUMBER(D17) -> FALSE | P17: =OR(N17=TRUE,O17=TRUE) -> TRUE
C18: =IF(P18=TRUE,C17+1,) -> 9 | D18: Retribución en especie | E18: =IF(P18=TRUE,E17+F17,) -> 91 | F18: 13 | G18: (Valoración dda. + ing.cta efec. – ing.cta repercutido) | N18: =ISTEXT(D18) -> TRUE | O18: =ISNUMBER(D18) -> FALSE | P18: =OR(N18=TRUE,O18=TRUE) -> TRUE
C19: =IF(P19=TRUE,C18+1,) -> 10 | D19: Valoración | E19: =IF(P19=TRUE,E18+F18,) -> 104 | F19: 13 | N19: =ISTEXT(D19) -> TRUE | O19: =ISNUMBER(D19) -> FALSE | P19: =OR(N19=TRUE,O19=TRUE) -> TRUE
C20: =IF(P20=TRUE,C19+1,) -> 11 | D20: Ingresos a cuenta | E20: =IF(P20=TRUE,E19+F19,) -> 117 | F20: 13 | N20: =ISTEXT(D20) -> TRUE | O20: =ISNUMBER(D20) -> FALSE | P20: =OR(N20=TRUE,O20=TRUE) -> TRUE
C21: =IF(P21=TRUE,C20+1,) -> 12 | D21: Ingresos a cuenta repercutido | E21: =IF(P21=TRUE,E20+F20,) -> 130 | F21: 13 | N21: =ISTEXT(D21) -> TRUE | O21: =ISNUMBER(D21) -> FALSE | P21: =OR(N21=TRUE,O21=TRUE) -> TRUE
C22: =IF(P22=TRUE,C21+1,) -> 13 | D22: Gastos deducibles | E22: =IF(P22=TRUE,E21+F21,) -> 143 | F22: 13 | N22: =ISTEXT(D22) -> TRUE | O22: =ISNUMBER(D22) -> FALSE | P22: =OR(N22=TRUE,O22=TRUE) -> TRUE
C23: =IF(P23=TRUE,C22+1,) -> 14 | D23: Reducciones | E23: =IF(P23=TRUE,E22+F22,) -> 156 | F23: 13 | N23: =ISTEXT(D23) -> TRUE | O23: =ISNUMBER(D23) -> FALSE | P23: =OR(N23=TRUE,O23=TRUE) -> TRUE
C24: =IF(P24=TRUE,C23+1,) -> 15 | D24: Retribuciones Dineraria Incapacidad Laboral | E24: =IF(P24=TRUE,E23+F23,) -> 169 | F24: 13 | N24: =ISTEXT(D24) -> TRUE | O24: =ISNUMBER(D24) -> FALSE | P24: =OR(N24=TRUE,O24=TRUE) -> TRUE
C25: =IF(P25=TRUE,C24+1,) -> 16 | D25: Retención Incapacidad Laboral | E25: =IF(P25=TRUE,E24+F24,) -> 182 | F25: 13 | N25: =ISTEXT(D25) -> TRUE | O25: =ISNUMBER(D25) -> FALSE | P25: =OR(N25=TRUE,O25=TRUE) -> TRUE
C26: =IF(P26=TRUE,C25+1,) -> 17 | D26: Retribución en Especie Incapacidad Laboral | E26: =IF(P26=TRUE,E25+F25,) -> 195 | F26: 13 | G26: (Valoración dda. IL. + ing.cta efec.IL – ing.cta repercutido IL) | N26: =ISTEXT(D26) -> TRUE | O26: =ISNUMBER(D26) -> FALSE | P26: =OR(N26=TRUE,O26=TRUE) -> TRUE
C27: =IF(P27=TRUE,C26+1,) -> 18 | D27: Valoración Incapacidad Laboral | E27: =IF(P27=TRUE,E26+F26,) -> 208 | F27: 13 | N27: =ISTEXT(D27) -> TRUE | O27: =ISNUMBER(D27) -> FALSE | P27: =OR(N27=TRUE,O27=TRUE) -> TRUE
C28: =IF(P28=TRUE,C27+1,) -> 19 | D28: Ingresos a cuenta Incapacidad Laboral | E28: =IF(P28=TRUE,E27+F27,) -> 221 | F28: 13 | N28: =ISTEXT(D28) -> TRUE | O28: =ISNUMBER(D28) -> FALSE | P28: =OR(N28=TRUE,O28=TRUE) -> TRUE
C29: =IF(P29=TRUE,C28+1,) -> 20 | D29: Ingresos a cuenta repercutido Incapacidad Laboral | E29: =IF(P29=TRUE,E28+F28,) -> 234 | F29: 13 | N29: =ISTEXT(D29) -> TRUE | O29: =ISNUMBER(D29) -> FALSE | P29: =OR(N29=TRUE,O29=TRUE) -> TRUE
C30: =IF(P30=TRUE,C29+1,) -> 0 | E30: =IF(P30=TRUE,E29+F29,) -> 0 | N30: =ISTEXT(D30) -> FALSE | O30: =ISNUMBER(D30) -> FALSE | P30: =OR(N30=TRUE,O30=TRUE) -> FALSE
C31: =IF(P31=TRUE,C30+1,) -> 0 | E31: =IF(P31=TRUE,E30+F30,) -> 0 | N31: =ISTEXT(D31) -> FALSE | O31: =ISNUMBER(D31) -> FALSE | P31: =OR(N31=TRUE,O31=TRUE) -> FALSE
C32: =IF(P32=TRUE,C31+1,) -> 0 | E32: =IF(P32=TRUE,E31+F31,) -> 0 | N32: =ISTEXT(D32) -> FALSE | O32: =ISNUMBER(D32) -> FALSE | P32: =OR(N32=TRUE,O32=TRUE) -> FALSE
C33: =IF(P33=TRUE,C32+1,) -> 0 | E33: =IF(P33=TRUE,E32+F32,) -> 0 | N33: =ISTEXT(D33) -> FALSE | O33: =ISNUMBER(D33) -> FALSE | P33: =OR(N33=TRUE,O33=TRUE) -> FALSE
C34: =IF(P34=TRUE,C33+1,) -> 0 | E34: =IF(P34=TRUE,E33+F33,) -> 0 | N34: =ISTEXT(D34) -> FALSE | O34: =ISNUMBER(D34) -> FALSE | P34: =OR(N34=TRUE,O34=TRUE) -> FALSE
C35: =IF(P35=TRUE,C34+1,) -> 0 | E35: =IF(P35=TRUE,E34+F34,) -> 0 | N35: =ISTEXT(D35) -> FALSE | O35: =ISNUMBER(D35) -> FALSE | P35: =OR(N35=TRUE,O35=TRUE) -> FALSE
C36: =IF(P36=TRUE,C35+1,) -> 0 | E36: =IF(P36=TRUE,E35+F35,) -> 0 | N36: =ISTEXT(D36) -> FALSE | O36: =ISNUMBER(D36) -> FALSE | P36: =OR(N36=TRUE,O36=TRUE) -> FALSE
C37: =IF(P37=TRUE,C36+1,) -> 0 | E37: =IF(P37=TRUE,E36+F36,) -> 0 | N37: =ISTEXT(D37) -> FALSE | O37: =ISNUMBER(D37) -> FALSE | P37: =OR(N37=TRUE,O37=TRUE) -> FALSE
C38: =IF(P38=TRUE,C37+1,) -> 0 | E38: =IF(P38=TRUE,E37+F37,) -> 0 | N38: =ISTEXT(D38) -> FALSE | O38: =ISNUMBER(D38) -> FALSE | P38: =OR(N38=TRUE,O38=TRUE) -> FALSE
C39: =IF(P39=TRUE,C38+1,) -> 0 | E39: =IF(P39=TRUE,E38+F38,) -> 0 | N39: =ISTEXT(D39) -> FALSE | O39: =ISNUMBER(D39) -> FALSE | P39: =OR(N39=TRUE,O39=TRUE) -> FALSE
C40: =IF(P40=TRUE,C39+1,) -> 0 | E40: =IF(P40=TRUE,E39+F39,) -> 0 | N40: =ISTEXT(D40) -> FALSE | O40: =ISNUMBER(D40) -> FALSE | P40: =OR(N40=TRUE,O40=TRUE) -> FALSE
C41: =IF(P41=TRUE,C40+1,) -> 0 | E41: =IF(P41=TRUE,E40+F40,) -> 0 | N41: =ISTEXT(D41) -> FALSE | O41: =ISNUMBER(D41) -> FALSE | P41: =OR(N41=TRUE,O41=TRUE) -> FALSE
... C99: =IF(P99=TRUE,C98+1,) -> 0 | E99: =IF(P99=TRUE,E98+F98,) -> 0 | N99: =ISTEXT(D99) -> FALSE | O99: =ISNUMBER(D99) -> FALSE | P99: =OR(N99=TRUE,O99=TRUE) -> FALSE

Sheet PP - Planes de Pensiones
D2: Diseño de registro de datos fiscales y personales
D3: ='CONTROL DE VERSIONES'!G68 -> IRPF 2025
D4: Planes de Pensiones
C5: =IF(P5=TRUE,C4+1,) -> 0
C6: =IF(P6=TRUE,C5+1,) -> 0
C7: Este concepto de datos fiscales incluye los datos por Planes de Pensiones con origen en el Modelo 345
C9: Nº | D9: Nombre | E9: Posición | F9: Longitud | G9: Descripción
C10: =IF(P10=TRUE,1,) -> 1 | D10: Tipo | E10: =IF(P10=TRUE,1,) -> 1 | F10: 1 | G10: Tipo de registro = '2' | N10: =ISTEXT(D10) -> TRUE | O10: =ISNUMBER(D10) -> FALSE | P10: =OR(N10=TRUE,O10=TRUE) -> TRUE
C11: =IF(P11=TRUE,C10+1,) -> 2 | D11: Código | E11: =IF(P11=TRUE,E10+F10,) -> 2 | F11: 7 | G11: 'PPnnnnn' Donde nnnn es el número del registro de este tipo contenido en el fichero de datos fiscales. | N11: =ISTEXT(D11) -> TRUE | O11: =ISNUMBER(D11) -> FALSE | P11: =OR(N11=TRUE,O11=TRUE) -> TRUE
C12: =IF(P12=TRUE,C11+1,) -> 3 | D12: NIF del Gestor/Promotor | E12: =IF(P12=TRUE,E11+F11,) -> 9 | F12: 9 | N12: =ISTEXT(D12) -> TRUE | O12: =ISNUMBER(D12) -> FALSE | P12: =OR(N12=TRUE,O12=TRUE) -> TRUE
C13: =IF(P13=TRUE,C12+1,) -> 4 | D13: Nombre del Gestor/Promotor | E13: =IF(P13=TRUE,E12+F12,) -> 18 | F13: 40 | N13: =ISTEXT(D13) -> TRUE | O13: =ISNUMBER(D13) -> FALSE | P13: =OR(N13=TRUE,O13=TRUE) -> TRUE
